2024-05-06 16:53:47.927844: E external/local_xla/xla/stream_executor/cuda/cuda_dnn.cc:9261] Unable to register cuDNN factory: Attempting to register factory for plugin cuDNN when one has already been registered
2024-05-06 16:53:47.927914: E external/local_xla/xla/stream_executor/cuda/cuda_fft.cc:607] Unable to register cuFFT factory: Attempting to register factory for plugin cuFFT when one has already been registered
2024-05-06 16:53:47.945346: E external/local_xla/xla/stream_executor/cuda/cuda_blas.cc:1515] Unable to register cuBLAS factory: Attempting to register factory for plugin cuBLAS when one has already been registered
2024-05-06 16:53:47.985934: I tensorflow/core/platform/cpu_feature_guard.cc:182] This TensorFlow binary is optimized to use available CPU instructions in performance-critical operations.
To enable the following instructions: AVX2 FMA, in other operations, rebuild TensorFlow with the appropriate compiler flags.
2024-05-06 16:53:49.169837: W tensorflow/compiler/tf2tensorrt/utils/py_utils.cc:38] TF-TRT Warning: Could not find TensorRT
Traceback (most recent call last):
  File "/home/z1974769/.conda/envs/condavisionenv/lib/python3.11/site-packages/pandas/core/indexes/base.py", line 3802, in get_loc
    return self._engine.get_loc(casted_key)
           ^^^^^^^^^^^^^^^^^^^^^^^^^^^^^^^^
  File "index.pyx", line 153, in pandas._libs.index.IndexEngine.get_loc
  File "index.pyx", line 182, in pandas._libs.index.IndexEngine.get_loc
  File "pandas/_libs/hashtable_class_helper.pxi", line 7081, in pandas._libs.hashtable.PyObjectHashTable.get_item
  File "pandas/_libs/hashtable_class_helper.pxi", line 7089, in pandas._libs.hashtable.PyObjectHashTable.get_item
KeyError: 'Goolge_swin_prediction'

The above exception was the direct cause of the following exception:

Traceback (most recent call last):
  File "/lstr/sahara/datalab-ml/z1974769/classifier/predict_images.py", line 107, in <module>
    column1 = pd.Series(df["Goolge_swin_prediction"])
                        ~~^^^^^^^^^^^^^^^^^^^^^^^^^^
  File "/home/z1974769/.conda/envs/condavisionenv/lib/python3.11/site-packages/pandas/core/frame.py", line 4090, in __getitem__
    indexer = self.columns.get_loc(key)
              ^^^^^^^^^^^^^^^^^^^^^^^^^
  File "/home/z1974769/.conda/envs/condavisionenv/lib/python3.11/site-packages/pandas/core/indexes/base.py", line 3809, in get_loc
    raise KeyError(key) from err
KeyError: 'Goolge_swin_prediction'
